[{"message": ["Error parsing type stubs for rapidfuzz.distance:", "Traceback (most recent call last):", "  File \"/home/runner/.cache/pypoetry/virtualenvs/pandas-fuzz-IEVTw6N2-py3.12/lib/python3.12/site-packages/pdoc/doc_pyi.py\", line 118, in include_typeinfo_from_stub_files", "    imported_stub = _import_stub_file(module.modulename, stub_file)", "                    ^^^^^^^^^^^^^^^^^^^^^^^^^^^^^^^^^^^^^^^^^^^^^^^", "  File \"/home/runner/.cache/pypoetry/virtualenvs/pandas-fuzz-IEVTw6N2-py3.12/lib/python3.12/site-packages/pdoc/doc_pyi.py\", line 52, in _import_stub_file", "    eval(code, m.__dict__, m.__dict__)", "  File \"/home/runner/.cache/pypoetry/virtualenvs/pandas-fuzz-IEVTw6N2-py3.12/lib/python3.12/site-packages/rapidfuzz/distance/__init__.pyi\", line 6, in <module>", "    from . import OSA as OSA", "ImportError: cannot import name 'OSA' from 'rapidfuzz' (/home/runner/.cache/pypoetry/virtualenvs/pandas-fuzz-IEVTw6N2-py3.12/lib/python3.12/site-packages/rapidfuzz/__init__.py)"], "category": "UserWarning", "filename": "/home/runner/.cache/pypoetry/virtualenvs/pandas-fuzz-IEVTw6N2-py3.12/lib/python3.12/site-packages/pdoc/doc_pyi.py", "lineno": 120}]